Workbook

Sheet Orders
A1: Item Code | B1: 8/3/2026 | C1: 8/10/2026 | D1: 8/17/2026 | E1: 8/24/2026 | F1: 8/31/2026
A2: 12008 | B2: 199500
A3: 12014 | C3: 27360
A4: 12032 | C4: 475000 | D4: 45600
A5: 12033 | D5: 51300 | F5: 62700
A6: 12040 | C6: 418000
A7: 12045 | C7: 51300
A8: 12046 | B8: 104500 | D8: 163400
A9: 12050 | F9: 190000
A10: 12081 | E10: 15200
A11: 12091 | D11: 15200
A12: 12103 | D12: 36100
A13: 12106 | D13: 45600
A14: 12117 | E14: 32300
A15: 12119. | E15: 15200
A16: 12122 | C16: 68400 | E16: 32300
A17: 12131 | B17: 157700
A18: 12140 | C18: 43700
A19: 12141 | C19: 83600
A20: 12146 | C20: 15960
A21: 12148 | C21: 45600
A22: 12153 | B22: 47500 | E22: 15200
A23: 12154 | D23: 15200
A24: 12158 | C24: 15960
A25: 12164 | C25: 19000
A26: 12167 | D26: 34200
A27: 12168 | B27: 47500 | E27: 15200
A28: 12170 | E28: 15200
A29: 12171 | D29: 45600
A30: 12172 | C30: 26600
A31: 12174 | D31: 177840
A32: 12175 | D32: 380760
A33: 12178 | C33: 15200
A34: 12186 | C34: 15960
A35: 12201 | D35: 66500
A36: 12204 | B36: 165300 | E36: 76000
A37: 12210 | C37: 43700
A38: 12228 | D38: 17100
A39: 12229 | D39: 51300
A40: 12234 | E40: 15200
...

Sheet Shipper#
A1: Week Name | B1: Shipper #
A2: 46237 | B2: 354827
A3: 46237 | B3: 354828
A4: 46237 | B4: 356138
A5: 46244 | B5: 356454
A6: 46244 | B6: 356565
A7: 46244 | B7: 355031
A8: 46244 | B8: 355032
A9: 46244 | B9: 355044
A10: 46244 | B10: 355045
A11: 46244 | B11: 355363
A12: 46244 | B12: 355033
A13: 46244 | B13: 355369
... A299: 46251 | B299: 355664

Sheet Sheet1
A1: Item Code | B1: Item Code2 | C1: Item Code3 | D1: Item Description | E1: Customer PO # | F1: Ship Date | G1: Shipper # | H1: Delivery Date | I1: Available to Ship | J1: Quantity | K1: Week Name
A2: Item Code: 12008
A3: DSC Part Number: 713-08107
B4: 12008 | C4: 12008 | D4: AG6-AP8 Classic Cream | E4: 0308057 | F4: 46240 | G4: 354827 | H4: 46242 | I4: 0 | J4: 95000 | K4: =IFERROR(VLOOKUP(H4,Sheet2!A:B,2,0),"") -> 46237
B5: 12008 | C5: 12008 | D5: AG6-AP8 Classic Cream | E5: 0308057 | F5: 46240 | G5: 354828 | H5: 46242 | J5: 95000 | K5: =IFERROR(VLOOKUP(H5,Sheet2!A:B,2,0),"") -> 46237
B6: 12008 | C6: 12008 | D6: AG6-AP8 Classic Cream | E6: 0308057 | F6: 46240 | G6: 356138 | H6: 46242 | J6: 9500 | K6: =IFERROR(VLOOKUP(H6,Sheet2!A:B,2,0),"") -> 46237
I7: 0 | J7: 199500 | K7: =IFERROR(VLOOKUP(H7,Sheet2!A:B,2,0),"")
K8: =IFERROR(VLOOKUP(H8,Sheet2!A:B,2,0),"")
A9: Item Code: 12014 | K9: =IFERROR(VLOOKUP(H9,Sheet2!A:B,2,0),"")
A10: DSC Part Number: 604-06739 | K10: =IFERROR(VLOOKUP(H10,Sheet2!A:B,2,0),"")
B11: 12014 | C11: 12014 | D11: AW6 Farmland Real Light 7oz | E11: 0308248 | F11: 46242 | G11: 356454 | H11: 46244 | I11: 0 | J11: 27360 | K11: =IFERROR(VLOOKUP(H11,Sheet2!A:B,2,0),"") -> 46244
I12: 0 | J12: 27360 | K12: =IFERROR(VLOOKUP(H12,Sheet2!A:B,2,0),"")
K13: =IFERROR(VLOOKUP(H13,Sheet2!A:B,2,0),"")
A14: Item Code: 12032 | K14: =IFERROR(VLOOKUP(H14,Sheet2!A:B,2,0),"")
A15: DSC Part Number: 713-05894 | K15: =IFERROR(VLOOKUP(H15,Sheet2!A:B,2,0),"")
B16: 12032 | C16: 12032 | D16: AR4 Darifair Whip Lt Crm Blue | E16: 0308238 | F16: 46243 | G16: 356565 | H16: 46245 | I16: 191900 | J16: 38000 | K16: =IFERROR(VLOOKUP(H16,Sheet2!A:B,2,0),"") -> 46244
B17: 12032 | C17: 12032 | D17: AR4 Darifair Whip Lt Crm Blue | E17: 0308238 | F17: 46244 | G17: 355031 | H17: 46246 | J17: 95000 | K17: =IFERROR(VLOOKUP(H17,Sheet2!A:B,2,0),"") -> 46244
B18: 12032 | C18: 12032 | D18: AR4 Darifair Whip Lt Crm Blue | E18: 0308238 | F18: 46244 | G18: 355032 | H18: 46246 | J18: 95000 | K18: =IFERROR(VLOOKUP(H18,Sheet2!A:B,2,0),"") -> 46244
B19: 12032 | C19: 12032 | D19: AR4 Darifair Whip Lt Crm Blue | E19: 0308238 | F19: 46244 | G19: 355044 | H19: 46246 | J19: 24700 | K19: =IFERROR(VLOOKUP(H19,Sheet2!A:B,2,0),"") -> 46244
B20: 12032 | C20: 12032 | D20: AR4 Darifair Whip Lt Crm Blue | E20: 0308238 | F20: 46244 | G20: 355045 | H20: 46246 | J20: 22800 | K20: =IFERROR(VLOOKUP(H20,Sheet2!A:B,2,0),"") -> 46244
B21: 12032 | C21: 12032 | D21: AR4 Darifair Whip Lt Crm Blue | E21: 0308238 | F21: 46244 | G21: 355363 | H21: 46246 | J21: 55100 | K21: =IFERROR(VLOOKUP(H21,Sheet2!A:B,2,0),"") -> 46244
B22: 12032 | C22: 12032 | D22: AR4 Darifair Whip Lt Crm Blue | E22: 0308238 | F22: 46245 | G22: 355033 | H22: 46247 | J22: 95000 | K22: =IFERROR(VLOOKUP(H22,Sheet2!A:B,2,0),"") -> 46244
B23: 12032 | C23: 12032 | D23: AR4 Darifair Whip Lt Crm Blue | E23: 0308327 | F23: 46245 | G23: 355369 | H23: 46247 | J23: 49400 | K23: =IFERROR(VLOOKUP(H23,Sheet2!A:B,2,0),"") -> 46244
B24: 12032 | C24: 12032 | D24: AR4 Darifair Whip Lt Crm Blue | E24: 0309024 | F24: 46255 | G24: 356175 | H24: 46257 | J24: 45600 | K24: =IFERROR(VLOOKUP(H24,Sheet2!A:B,2,0),"") -> 46251
I25: 191900 | J25: 520600 | K25: =IFERROR(VLOOKUP(H25,Sheet2!A:B,2,0),"")
K26: =IFERROR(VLOOKUP(H26,Sheet2!A:B,2,0),"")
A27: Item Code: 12033 | K27: =IFERROR(VLOOKUP(H27,Sheet2!A:B,2,0),"")
A28: DSC Part Number: 713-05898 | K28: =IFERROR(VLOOKUP(H28,Sheet2!A:B,2,0),"")
B29: 12033 | C29: 12033 | D29: AZ12 Darifair Light - Yellow | E29: 0308315 | F29: 46249 | G29: 355011 | H29: 46251 | I29: 98800 | J29: 51300 | K29: =IFERROR(VLOOKUP(H29,Sheet2!A:B,2,0),"") -> 46251
B30: 12033 | C30: 12033 | D30: AZ12 Darifair Light - Yellow | E30: 0309055 | F30: 46263 | G30: 356200 | H30: 46265 | J30: 62700 | K30: =IFERROR(VLOOKUP(H30,Sheet2!A:B,2,0),"") -> 46265
I31: 98800 | J31: 114000 | K31: =IFERROR(VLOOKUP(H31,Sheet2!A:B,2,0),"")
K32: =IFERROR(VLOOKUP(H32,Sheet2!A:B,2,0),"")
A33: Item Code: 12040 | K33: =IFERROR(VLOOKUP(H33,Sheet2!A:B,2,0),"")
A34: DSC Part Number: 713-05902 | K34: =IFERROR(VLOOKUP(H34,Sheet2!A:B,2,0),"")
B35: 12040 | C35: 12040 | D35: AC4 James Farm Whip Lt Crm | E35: 0307105 | F35: 46244 | G35: 355185 | H35: 46246 | I35: 380 | J35: 95000 | K35: =IFERROR(VLOOKUP(H35,Sheet2!A:B,2,0),"") -> 46244
B36: 12040 | C36: 12040 | D36: AC4 James Farm Whip Lt Crm | E36: 0307105 | F36: 46244 | G36: 355186 | H36: 46246 | J36: 95000 | K36: =IFERROR(VLOOKUP(H36,Sheet2!A:B,2,0),"") -> 46244
B37: 12040 | C37: 12040 | D37: AC4 James Farm Whip Lt Crm | E37: 0307105 | F37: 46244 | G37: 355187 | H37: 46246 | J37: 19000 | K37: =IFERROR(VLOOKUP(H37,Sheet2!A:B,2,0),"") -> 46244
B38: 12040 | C38: 12040 | D38: AC4 James Farm Whip Lt Crm | E38: 0308322 | F38: 46245 | G38: 355365 | H38: 46247 | J38: 19000 | K38: =IFERROR(VLOOKUP(H38,Sheet2!A:B,2,0),"") -> 46244
B39: 12040 | C39: 12040 | D39: AC4 James Farm Whip Lt Crm | E39: 0308322 | F39: 46245 | G39: 355366 | H39: 46247 | J39: 95000 | K39: =IFERROR(VLOOKUP(H39,Sheet2!A:B,2,0),"") -> 46244
B40: 12040 | C40: 12040 | D40: AC4 James Farm Whip Lt Crm | E40: 0308322 | F40: 46245 | G40: 355367 | H40: 46247 | J40: 95000 | K40: =IFERROR(VLOOKUP(H40,Sheet2!A:B,2,0),"") -> 46244
...

Sheet Sheet2
A1: Date | B1: Start Week
A2: 46023 | B2: 46020
A3: 46024 | B3: 46020
A4: 46025 | B4: 46020
A5: 46026 | B5: 46020
A6: 46027 | B6: 46027
A7: 46028 | B7: 46027
A8: 46029 | B8: 46027
A9: 46030 | B9: 46027
A10: 46031 | B10: 46027
A11: 46032 | B11: 46027
A12: 46033 | B12: 46027
A13: 46034 | B13: 46034
... A366: 46387 | B366: 46384
